# French translations for Open-Capture For Invoices
# Copyright (C) 2019 ORGANIZATION
# This file is distributed under the same license as the project
# FIRST AUTHOR <nathan.cheval@edissyum.com>, 2021.
msgid ""
msgstr ""
"Project-Id-Version:  0.1\n"
"Report-Msgid-Bugs-To: nathan.cheval@edissyum.com\n"
"POT-Creation-Date: 2022-07-29 16:47+0200\n"
"PO-Revision-Date: 2019-09-02 17:48+0200\n"
"Last-Translator: Nathan CHEVAL <nathan.cheval@edissyum.com>\n"
"Language: fr\n"
"Language-Team: fr <nathan.cheval@edissyum.com>\n"
"Plural-Forms: nplurals=2; plural=(n > 1)\n"
"MIME-Version: 1.0\n"
"Content-Type: text/plain; charset=utf-8\n"
"Content-Transfer-Encoding: 8bit\n"
"Generated-By: Babel 2.9.1\n"

#: src/backend/verifier_exports.py:71 src/backend/verifier_exports.py:74
msgid "XML_DESTINATION_FOLDER_DOESNT_EXISTS"
msgstr "Le dossier de destination XML n'existe pas"

#: src/backend/controllers/splitter.py:278
#: src/backend/controllers/splitter.py:284 src/backend/verifier_exports.py:220
#: src/backend/verifier_exports.py:226 src/backend/verifier_exports.py:232
msgid "EXPORT_MAARCH_ERROR"
msgstr "Erreur lors de l'export vers Maarch"

#: src/backend/verifier_exports.py:227
msgid "PDF_FILE_NOT_FOUND"
msgstr "Le fichier PDF est introuvable"

#: src/backend/verifier_exports.py:238
msgid "MAARCH_WS_INFO_WRONG"
msgstr "Les informations de connexion à Maarch sont erronées"

#: src/backend/controllers/splitter.py:290 src/backend/verifier_exports.py:244
msgid "MAARCH_WS_INFO_EMPTY"
msgstr "Les informations de connexion à Maarch sont vides"

#: src/backend/classes/MaarchWebServices.py:39
msgid "HOST_NOT_FOUND"
msgstr "L'URL de l'hôte n'existe pas"

#: src/backend/controllers/accounts.py:46 src/backend/models/accounts.py:55
msgid "GET_SUPPLIER_BY_ID_ERROR"
msgstr "Erreur lors de la récupération du compte fournisseur"

#: src/backend/controllers/accounts.py:59 src/backend/models/accounts.py:75
msgid "GET_ADDRESS_BY_ID_ERROR"
msgstr "Erreur lors de la récupération de l'adresse"

#: src/backend/controllers/accounts.py:80
#: src/backend/controllers/accounts.py:138
msgid "UPDATE_SUPPLIER_POSITIONS_ERROR"
msgstr "Erreur lors de la mise à jour des positions du compte fournisseur"

#: src/backend/controllers/accounts.py:101
#: src/backend/controllers/accounts.py:107
msgid "UPDATE_SUPPLIER_ERROR"
msgstr "Erreur lors de la mise à jour du fournisseur"

#: src/backend/controllers/accounts.py:169
msgid "UPDATE_SUPPLIER_PAGES_ERROR"
msgstr "Erreur lors de la mise à jour des pages du compte fournisseur"

#: src/backend/controllers/accounts.py:193
#: src/backend/controllers/accounts.py:199
#: src/backend/controllers/accounts.py:223
#: src/backend/controllers/accounts.py:229 src/backend/models/accounts.py:115
msgid "UPDATE_ADDRESS_ERROR"
msgstr "Erreur lors de la mise à jour de l'adresse"

#: src/backend/controllers/accounts.py:253 src/backend/models/accounts.py:132
msgid "CREATE_ADDRESS_ERROR"
msgstr "Erreur lors de la création de l'adresse"

#: src/backend/controllers/accounts.py:290
#: src/backend/controllers/accounts.py:296 src/backend/models/accounts.py:149
msgid "CREATE_SUPPLIER_ERROR"
msgstr "Erreur lors de la création du compte fournisseur"

#: src/backend/controllers/accounts.py:297
msgid "SUPPLIER_VAT_NUMBER_ALREADY_EXISTS"
msgstr "Un compte fournisseur existe déjà avec ce numéro de TVA"

#: src/backend/controllers/accounts.py:317 src/backend/controllers/user.py:115
#: src/backend/models/accounts.py:204 src/backend/models/accounts.py:224
#: src/backend/models/accounts.py:240 src/backend/models/user.py:162
msgid "GET_CUSTOMER_BY_ID_ERROR"
msgstr "Erreur lors de la récupération du compte client"

#: src/backend/controllers/accounts.py:357
#: src/backend/controllers/accounts.py:363 src/backend/models/accounts.py:259
msgid "UPDATE_CUSTOMER_ERROR"
msgstr "Erreur lors de la mise à jour du compte client"

#: src/backend/controllers/accounts.py:391
#: src/backend/controllers/accounts.py:397 src/backend/models/accounts.py:276
msgid "CREATE_CUSTOMER_ERROR"
msgstr "Erreur lors de la création du compte client"

#: src/backend/controllers/accounts.py:398
msgid "CUSTOMER_VAT_NUMBER_ALREADY_EXISTS"
msgstr "Un compte client existe déjà avec ce numéro de TVA"

#: src/backend/controllers/accounts.py:412
#: src/backend/controllers/accounts.py:418 src/backend/models/accounts.py:295
msgid "DELETE_CUSTOMER_ERROR"
msgstr "Erreur lors de la suppression du compte client"

#: src/backend/controllers/accounts.py:433
#: src/backend/controllers/accounts.py:439 src/backend/models/accounts.py:168
msgid "DELETE_SUPPLIER_ERROR"
msgstr "Erreur lors de la suppression du compte fournisseur"

#: src/backend/controllers/accounts.py:460
msgid "LOAD_SUPPLIER_REFERENCIAL_ERROR"
msgstr "Erreur lors du chargement du référentiel fournisseur"

#: src/backend/controllers/auth.py:84 src/backend/controllers/auth.py:128
#: src/backend/rest/auth.py:89 src/backend/rest/auth.py:204
#: src/backend/rest/auth.py:209
msgid "LOGIN_ERROR"
msgstr "Erreur lors de la connexion"

#: src/backend/controllers/auth.py:99 src/backend/controllers/auth.py:107
#: src/backend/controllers/auth.py:109
msgid "JWT_ERROR"
msgstr "Erreur lors de l'authentification par token"

#: src/backend/controllers/auth.py:184
msgid "LOADING_METHODS_AUTH_ERROR"
msgstr "Echec lors de l'exécution de la requête"

#: src/backend/controllers/auth.py:196
msgid "DISABLE_LOGIN_METHOD_ERROR"
msgstr "Erreur lors de la désactivation de cette méthode"

#: src/backend/controllers/auth.py:208
msgid "ENABLE_LOGIN_METHOD_ERROR"
msgstr "Erreur lors de l'activation de cette méthode"

#: src/backend/controllers/config.py:169 src/backend/models/config.py:182
msgid "UPDATE_DOCSERVER_ERROR"
msgstr "Erreur lors de la mise à jour de la docserver"

#: src/backend/controllers/config.py:206 src/backend/controllers/config.py:216
msgid "ERROR_UPDATING_IMAGE"
msgstr "Erreur lors de la mise à jour de l'image de connexion"

#: src/backend/controllers/config.py:207
msgid "CUSTOM_IMAGE_PATH_NOT_WRITEABLE"
msgstr "Le dossier d'image du custom n'est pas accessible"

#: src/backend/controllers/config.py:217
msgid "CUSTOM_NOT_PRESENT"
msgstr "Aucun custom n'est présent"

#: src/backend/controllers/doctypes.py:136
msgid "DOCTYPESEPARATOR"
msgstr "SEPARATEUR AVEC TYPE DE DOCUMENT / SEPARATOR WITH DOCUMENT TYPE"

#: src/backend/controllers/doctypes.py:139
msgid "DOCUMENTSEPARATOR"
msgstr "SEPARATEUR DE DOCUMENT / DOCUMENT SEPARATOR"

#: src/backend/controllers/doctypes.py:142
msgid "BUNDLESEPARATOR"
msgstr "SEPARATEUR DE LOT / BUNDLE SEPARATOR"

#: src/backend/controllers/forms.py:76 src/backend/controllers/forms.py:125
#: src/backend/models/forms.py:57
msgid "GET_FORM_BY_ID_ERROR"
msgstr "Erreur lors de la récupération du formulaire"

#: src/backend/controllers/forms.py:108
msgid "GET_FORM_FIELDS_BY_FORM_ID_ERROR"
msgstr "Erreur lors de la récupération des champs du formulaire"

#: src/backend/controllers/forms.py:169 src/backend/controllers/forms.py:175
msgid "DELETE_FORM_ERROR"
msgstr "Erreur lors de la suppression du formulaire"

#: src/backend/controllers/forms.py:184 src/backend/controllers/inputs.py:69
#: src/backend/controllers/outputs.py:54
#: src/backend/controllers/positions_masks.py:159
msgid "COPY_OF"
msgstr "Copie de"

#: src/backend/controllers/forms.py:201 src/backend/controllers/forms.py:207
msgid "DUPLICATE_FORM_ERROR"
msgstr "Erreur lors de la duplication du formulaire"

#: src/backend/controllers/forms.py:221 src/backend/controllers/forms.py:227
msgid "DISABLE_FORM_ERROR"
msgstr "Erreur lors de la désactivation du formulaire"

#: src/backend/controllers/forms.py:241 src/backend/controllers/forms.py:247
msgid "ENABLE_FORM_ERROR"
msgstr "Erreur lors de l'activation du formulaire"

#: src/backend/controllers/forms.py:277 src/backend/controllers/forms.py:283
msgid "UPDATE_FORMS_FIELDS_ERROR"
msgstr "Erreur lors de la mise à jour des champs du formulaire"

#: src/backend/controllers/history.py:28
msgid "ADD_HISTORY_ERROR"
msgstr "Erreur lors de l'ajout dans l'historique"

#: src/backend/controllers/inputs.py:51 src/backend/controllers/inputs.py:57
msgid "UPDATE_INPUT_ERROR"
msgstr "Erreur lors de la mise à jour de la chaîne entrante"

#: src/backend/controllers/inputs.py:82 src/backend/controllers/inputs.py:88
msgid "DUPLICATE_INPUT_ERROR"
msgstr "Erreur lors de la duplication de la chaîne entrante"

#: src/backend/controllers/inputs.py:113 src/backend/controllers/inputs.py:124
#: src/backend/controllers/inputs.py:137
msgid "CREATE_INPUT_ERROR"
msgstr "Erreur lors de la création de la chaîne entrante"

#: src/backend/controllers/inputs.py:114
msgid "INPUT_ID_ALREADY_EXISTS"
msgstr "Le libellé technique de la chaîne entrante existe déjà"

#: src/backend/controllers/inputs.py:125
msgid "INPUT_FOLDER_ALREADY_EXISTS"
msgstr "Le chemin de capture est déjà paramétré dans une autre chaîne entrante"

#: src/backend/controllers/inputs.py:150
msgid "GET_INPUT_BY_ID_ERROR"
msgstr "Erreur lors de récupération de la chaîne entrante"

#: src/backend/controllers/inputs.py:171 src/backend/controllers/inputs.py:177
msgid "DELETE_INPUT_ERROR"
msgstr "Erreur lors de le suppression de la chaîne entrante"

#: src/backend/controllers/inputs.py:209
msgid "FS_WATCHER_DELETION_ERROR"
msgstr "Erreur lors de la suppression des paramètres du fs watcher"

#: src/backend/controllers/inputs.py:210 src/backend/controllers/inputs.py:272
msgid "FS_WATCHER_CONFIG_DOESNT_EXIST"
msgstr "La configuration du fs watcher est introuvable"

#: src/backend/controllers/inputs.py:251 src/backend/controllers/inputs.py:271
msgid "FS_WATCHER_CREATION_ERROR"
msgstr "Erreur lors de la création des paramètres du fs watcher"

#: src/backend/controllers/inputs.py:252
msgid "CAN_NOT_CREATE_FOLDER_PERMISSION_ERROR"
msgstr "Problème de permissions pour créer le dossier"

#: src/backend/controllers/inputs.py:277
msgid "SCRIPT_SAMPLE_DOESNT_EXISTS"
msgstr "Le script d'exemple n'existe pas"

#: src/backend/controllers/inputs.py:283
msgid "SCRIPT_FOLDER_DOESNT_EXISTS"
msgstr "Le dossier des scripts n'existe pas"

#: src/backend/controllers/outputs.py:61 src/backend/controllers/outputs.py:67
msgid "DUPLICATE_OUTPUT_ERROR"
msgstr "Erreur lors de la duplication de la chaîne sortante"

#: src/backend/controllers/outputs.py:91 src/backend/controllers/outputs.py:97
msgid "UPDATE_OUTPUT_ERROR"
msgstr "Erreur lors de mise à jour de la chaîne sortante"

#: src/backend/controllers/outputs.py:120
msgid "CREATE_OUTPUT_ERROR"
msgstr "Erreur lors de la création de la chaîne sortante"

#: src/backend/controllers/outputs.py:133
msgid "GET_OUTPUT_BY_ID_ERROR"
msgstr "Erreur lors de la récupération de la chaîne sortante"

#: src/backend/controllers/outputs.py:146
msgid "GET_OUTPUT_TYPE_BY_ID_ERROR"
msgstr "Erreur lors de la récupération des types de chaîne sortante"

#: src/backend/controllers/outputs.py:160
#: src/backend/controllers/outputs.py:166
msgid "DELETE_OUTPUT_ERROR"
msgstr "Erreur lors de la suppression de la chaîne sortante"

#: src/backend/controllers/positions_masks.py:77
#: src/backend/controllers/positions_masks.py:94
msgid "GET_POSITION_MASK_BY_ID_ERROR"
msgstr "Erreur lors de la récupération du masque de positionnement"

#: src/backend/controllers/positions_masks.py:141
#: src/backend/controllers/positions_masks.py:147
msgid "DELETE_POSITION_MASK_ERROR"
msgstr "Erreur lors de la suppression du masque de positionnement"

#: src/backend/controllers/positions_masks.py:175
#: src/backend/controllers/positions_masks.py:181
msgid "DUPLICATE_POSITIONS_MASKS_ERROR"
msgstr "Erreur lors de la duplication du masque de positionnement"

#: src/backend/controllers/positions_masks.py:199
#: src/backend/controllers/positions_masks.py:205
msgid "DISABLE_POSITION_MASK_ERROR"
msgstr "Erreur lors de désactivation du masque de positionnement"

#: src/backend/controllers/positions_masks.py:223
#: src/backend/controllers/positions_masks.py:229
msgid "ENABLE_POSITION_MASK_ERROR"
msgstr "Erreur lors de l'activation du masque de positionnement"

#: src/backend/controllers/positions_masks.py:255
msgid "UPDATE_POSITIONS_BY_POSITIONS_MASK_ID_ERROR"
msgstr "Erreur lors de la mise à jour des positions du masque de positionnement"

#: src/backend/controllers/positions_masks.py:281
msgid "UPDATE_PAGES_BY_POSITIONS_MASK_ID_ERROR"
msgstr "Erreur lors de la mise à jour des pages du masque de positionnement"

#: src/backend/controllers/positions_masks.py:302
msgid "DELETE_POSITIONS_BY_POSITION_MASK_ID_ERROR"
msgstr "Erreur lors de la suppression des positions du masque de positionnement"

#: src/backend/controllers/positions_masks.py:323
msgid "DELETE_PAGES_BY_POSITION_MASK_ID_ERROR"
msgstr "Erreur lors de la suppression des pages du masque de positionnement"

#: src/backend/controllers/privileges.py:37
#: src/backend/controllers/privileges.py:65
msgid "GET_PRIVILEGES_ERROR"
msgstr "Erreur lors de la récupération des privilèges"

#: src/backend/controllers/roles.py:47 src/backend/controllers/roles.py:53
#: src/backend/controllers/roles.py:95 src/backend/controllers/roles.py:101
#: src/backend/models/roles.py:75
msgid "UPDATE_ROLE_ERROR"
msgstr "Erreur lors de la mise à jour du rôle"

#: src/backend/controllers/roles.py:75 src/backend/models/roles.py:92
msgid "CREATE_ROLE_ERROR"
msgstr "Erreur lors de la création du rôle"

#: src/backend/controllers/roles.py:114
msgid "GET_ROLE_BY_ID_ERROR"
msgstr "Erreur lors de la récupération du rôle"

#: src/backend/controllers/roles.py:128 src/backend/controllers/roles.py:134
msgid "DELETE_ROLE_ERROR"
msgstr "Erreur lors de la suppression du rôle"

#: src/backend/controllers/roles.py:148 src/backend/controllers/roles.py:154
msgid "DISABLE_ROLE_ERROR"
msgstr "Erreur lors de la désactivation du rôle"

#: src/backend/controllers/roles.py:168 src/backend/controllers/roles.py:174
msgid "ENABLE_ROLE_ERROR"
msgstr "Erreur lors de l'activation du rôle"

#: src/backend/controllers/splitter.py:83
msgid "LOAD_METADATA_ERROR"
msgstr "Erreur du chargement des métadonnées"

#: src/backend/controllers/splitter.py:111
#: src/backend/controllers/verifier.py:76
msgid "AT"
msgstr "à"

#: src/backend/controllers/splitter.py:226
msgid "ADD_DOCUMENT_ERROR"
msgstr "Erreur lors de l'ajout d'un document"

#: src/backend/controllers/splitter.py:340
#: src/backend/controllers/splitter.py:573
msgid "EXPORT_PDF_ERROR"
msgstr "Erreur lors de l'export PDF"

#: src/backend/controllers/splitter.py:362
#: src/backend/controllers/splitter.py:594
msgid "EXPORT_XML_ERROR"
msgstr "Erreur lors de l'export XML"

#: src/backend/controllers/splitter.py:378
msgid "UPDATE_BATCH_ERROR"
msgstr "Erreur lors de la mise à jour du lot"

#: src/backend/controllers/splitter.py:390
msgid "UPDATE_DOCUMENTS_ERROR"
msgstr "Erreur lors de la mise à jour du document"

#: src/backend/controllers/splitter.py:403
msgid "UPDATE_DOCUMENT_ERROR"
msgstr "Erreur lors de la mise à jour du document"

#: src/backend/controllers/splitter.py:418
#: src/backend/controllers/splitter.py:439
#: src/backend/controllers/splitter.py:454
#: src/backend/controllers/splitter.py:469
msgid "UPDATE_PAGES_ERROR"
msgstr "Erreur lors de la modification des pages"

#: src/backend/controllers/splitter.py:483
msgid "CMIS_CONNECTION_ERROR"
msgstr "Erreur lors de la connexion CMIS"

#: src/backend/controllers/splitter.py:668
#: src/backend/controllers/verifier.py:521 src/backend/models/splitter.py:423
#: src/backend/models/verifier.py:153
msgid "GET_TOTALS_ERROR"
msgstr "Erreur lors de la récupération des totaux"

#: src/backend/controllers/status.py:31
msgid "RETRIEVES_STATUS_ERROR"
msgstr "Erreur lors de la récupération des status"

#: src/backend/controllers/user.py:30
msgid "CREATE_USER_ERROR"
msgstr "Erreur lors de la création de l'utilisateur"

#: src/backend/controllers/user.py:68 src/backend/models/user.py:121
#: src/backend/models/user.py:142
msgid "GET_USER_BY_ID_ERROR"
msgstr "Erreur lors de la récupération de l'utilisateur"

#: src/backend/controllers/user.py:85
msgid "GET_USER_BY_USERNAME_ERROR"
msgstr "Erreur lors de la récupération de l'utilisateur"

#: src/backend/controllers/user.py:127
msgid "UPDATE_PROFILE"
msgstr "Mise à jour du profile"

#: src/backend/controllers/user.py:128
msgid "ERROR_OLD_PASSWORD_NOT_MATCH"
msgstr "L'ancien mot de passe ne corresponds pas"

#: src/backend/controllers/user.py:133
msgid "UPDATE_USER"
msgstr "Mise à jour de l'utilisateur"

#: src/backend/controllers/user.py:134
msgid "ERROR_PASSWORD_NOT_MATCH"
msgstr "Les mots de passes ne correspondent pas"

#: src/backend/controllers/user.py:161 src/backend/controllers/user.py:167
#: src/backend/models/user.py:182
msgid "UPDATE_USER_ERROR"
msgstr "Erreur lors de la mise à jour de l'utilisateur"

#: src/backend/controllers/user.py:181 src/backend/controllers/user.py:187
msgid "DELETE_USER_ERROR"
msgstr "Erreur lors de la suppression de l'utilisateur"

#: src/backend/controllers/user.py:201 src/backend/controllers/user.py:207
msgid "DISABLE_USER_ERROR"
msgstr "Erreur lors de désactiver de l'utilisateur"

#: src/backend/controllers/user.py:221 src/backend/controllers/user.py:227
msgid "ENABLE_USER_ERROR"
msgstr "Erreur lors de l'activation de l'utilisateur"

#: src/backend/controllers/user.py:244 src/backend/controllers/user.py:250
#: src/backend/models/user.py:201
msgid "UPDATE_CUSTOMERS_USER_ERROR"
msgstr "Erreur lors de la mise à jour des comptes clients de l'utilisateur"

#: src/backend/controllers/verifier.py:57 src/backend/models/verifier.py:37
msgid "GET_INVOICE_BY_ID_ERROR"
msgstr "Erreur lors de la récupération de la facture"

#: src/backend/controllers/verifier.py:168
#: src/backend/controllers/verifier.py:266
msgid "UPDATE_INVOICE_POSITIONS_ERROR"
msgstr "Erreur lors de la mise à jour des positions de la facture"

#: src/backend/controllers/verifier.py:191
#: src/backend/controllers/verifier.py:284
msgid "UPDATE_INVOICE_PAGES_ERROR"
msgstr "Erreur lors de la mise à jour des pages de la facture"

#: src/backend/controllers/verifier.py:213
#: src/backend/controllers/verifier.py:231
msgid "UPDATE_INVOICE_DATA_ERROR"
msgstr "Erreur lors de la mise à jour des données de la facture"

#: src/backend/controllers/verifier.py:298
#: src/backend/controllers/verifier.py:304
msgid "DELETE_INVOICE_ERROR"
msgstr "Erreur lors de la suppression de la facture"

#: src/backend/controllers/verifier.py:319
#: src/backend/controllers/verifier.py:325
msgid "UPDATE_INVOICE_ERROR"
msgstr "Erreur lors de la mise à jour de la facture"

#: src/backend/controllers/verifier.py:342
msgid "REMOVE_LOCK_BY_USER_ID_ERROR"
msgstr "Erreur lors de la suppression du verrou sur la facture"

#: src/backend/controllers/verifier.py:432
#: src/backend/controllers/verifier.py:435
#: src/backend/controllers/verifier.py:449
#: src/backend/controllers/verifier.py:468
#: src/backend/controllers/verifier.py:469
msgid "API_INSEE_ERROR_CONNEXION"
msgstr "Erreur lors de la connexion à l'api de l'INSEE"

#: src/backend/controllers/verifier.py:493
msgid "VAT_NOT_VALID"
msgstr "Numéro de TVA invalide"

#: src/backend/controllers/verifier.py:498
#: src/backend/controllers/verifier.py:499
msgid "VAT_API_ERROR"
msgstr "Impossible de joindre l'API de vérification du numéro de TVA"

#: src/backend/models/accounts.py:96
msgid "SUPPLIER_UPDATE_ERROR"
msgstr "Erreur lors de la mise à jour du fournisseur"

#: src/backend/models/auth.py:40 src/backend/models/auth.py:92
#: src/backend/models/user.py:40 src/backend/rest/auth.py:90
msgid "BAD_USERNAME"
msgstr "Mauvais nom de compte"

#: src/backend/models/auth.py:42 src/backend/models/user.py:42
msgid "BAD_PASSWORD"
msgstr "Mauvais mot de passe"

#: src/backend/models/auth.py:44
msgid "USER_DELETED"
msgstr "Utilisateur supprimé"

#: src/backend/models/auth.py:46
msgid "USER_DISABLED"
msgstr "Utilisateur desactivé"

#: src/backend/models/auth.py:64 src/backend/models/auth.py:74
#: src/backend/models/roles.py:54
msgid "ROLE_DOESNT_EXISTS"
msgstr "Le rôle n'existe pas"

#: src/backend/models/auth.py:123 src/backend/rest/auth.py:224
msgid "NO_LDAP_CONFIGURATIONS_FOUND"
msgstr "Aucune configurations LDAP n'est disponible"

#: src/backend/models/auth.py:145
msgid "UPDATE_LOGIN_METHOD_ERROR"
msgstr "Erreur lors de la mise à jour de la méthode d'authentification"

#: src/backend/models/auth.py:185
msgid "DISABLE_LOGIN_METHOD_DATA_ERROR"
msgstr "Erreur lors de la désactivation de cette méthode d'authentification"

#: src/backend/models/auth.py:204
msgid "ENABLE_LOGIN_METHOD_DATA_ERROR"
msgstr "Erreur lors de l'activation de cette méthode d'authentification"

#: src/backend/models/config.py:140
msgid "UPDATE_CONFIGURATION_ERROR"
msgstr "Erreur lors de la mise à jour de la configuration"

#: src/backend/models/config.py:159
msgid "UPDATE_REGEX_ERROR"
msgstr "Erreur lors de la mise à jour des REGEX"

#: src/backend/models/custom_fields.py:52
msgid "ADD_CUSTOM_FIELD_ERROR"
msgstr "Erreur lors de la création du champ custom"

#: src/backend/models/custom_fields.py:55
msgid "CUSTOM_FIELD_ALREADY_EXIST"
msgstr "Le champ custom existe déjà"

#: src/backend/models/custom_fields.py:98
msgid "UPDATE_CUSTOM_FIELDS_ERROR"
msgstr "Erreur lors de la mise à jour du champ custom"

#: src/backend/models/custom_fields.py:119
msgid "DELETE_CUSTOM_FIELDS_ERROR"
msgstr "Erreur lors de la suppression du champ custom"

#: src/backend/models/doctypes.py:48
msgid "ADD_DOCTYPE_ERROR"
msgstr "Erreur lors de l'ajout d'un type de document"

#: src/backend/models/doctypes.py:51
msgid "DOCTYPE_ALREADY_EXIST"
msgstr "Le type de document existe déjà"

#: src/backend/models/doctypes.py:90
msgid "UPDATE_DOCTYPE_ERROR"
msgstr "Erreur lors de la mise à jour du type de document"

#: src/backend/models/doctypes.py:118 src/backend/models/doctypes.py:121
msgid "SET_DEFAULT_DOCTYPE_ERROR"
msgstr "Erreur lors de la modification du type de document par défaut"

#: src/backend/models/forms.py:77
msgid "GET_DEFAULT_FORM_ERROR"
msgstr "Erreur lors de la récupération du formulaire par défaut"

#: src/backend/models/forms.py:98
msgid "UPDATE_FORM_ERROR"
msgstr "Erreur lors de la mise à jour du formulaire"

#: src/backend/models/forms.py:117
msgid "UPDATE_FORM_FIELDS_ERROR"
msgstr "Erreur lors de la mise à jour des champs du formulaire"

#: src/backend/models/forms.py:170
msgid "ADD_FORM_ERROR"
msgstr "Erreur lors de la création du formulaire"

#: src/backend/models/forms.py:173
msgid "FORM_LABEL_ALREADY_EXIST"
msgstr "Le libellé de formulaire existe déjà"

#: src/backend/models/inputs.py:54
msgid "INPUT_DOESNT_EXISTS"
msgstr "La chaîne entrante n'existe pas"

#: src/backend/models/inputs.py:90
msgid "INPUT_UPDATE_ERROR"
msgstr "Erreur lors de la mise à jour de la chaîne entrante"

#: src/backend/models/inputs.py:107
msgid "INPUT_CREATE_ERROR"
msgstr "Erreur lors de la création de la chaîne entrante"

#: src/backend/models/outputs.py:69
msgid "OUTPUT_DOESNT_EXISTS"
msgstr "La chaîne sortante n'existe pas"

#: src/backend/models/outputs.py:89
msgid "OUTPUT_TYPE_DOESNT_EXISTS"
msgstr "Le type de chaîne sortante n'existe aps"

#: src/backend/models/outputs.py:110
msgid "OUTPUT_UPDATE_ERROR"
msgstr "Erreur lors de la mise à jour de la chaîne sortante"

#: src/backend/models/outputs.py:127
msgid "OUTPUT_CREATE_ERROR"
msgstr "Erreur lors de la création de la chaîne sortante"

#: src/backend/models/positions_masks.py:57
msgid "GET_POSITIONS_MASKS_BY_ID_ERROR"
msgstr "Erreur lors de la récupération du masque de positionnement"

#: src/backend/models/positions_masks.py:78
msgid "UPDATE_POSITIONS_MASKS_ERROR"
msgstr "Erreur lors de la mise à jour du masque de positionnement"

#: src/backend/models/positions_masks.py:97
msgid "UPDATE_POSITIONS_MASKS_FIELDS_ERROR"
msgstr "Erreur lors de la mise à jour des champs du masque de positionnement"

#: src/backend/models/positions_masks.py:129
msgid "ADD_POSITIONS_MASKS_ERROR"
msgstr "Erreur lors de la création du masque de positionnement"

#: src/backend/models/positions_masks.py:132
msgid "POSITIONS_MASK_LABEL_ALREADY_EXIST"
msgstr "Le libellé du masque de positionnement existe déjà"

#: src/backend/models/privileges.py:35 src/backend/models/privileges.py:53
msgid "ERROR_RETRIEVING_PRIVILEGES"
msgstr "Erreur lors de la récupération des privilèges"

#: src/backend/models/roles.py:111
msgid "ROLE_PRIVILEGES_UPDATE_ERROR"
msgstr "Erreur lors de la mise à jour des privilèges du rôle"

#: src/backend/models/roles.py:130
msgid "ROLE_PRIVILEGES_CREATE_ERROR"
msgstr "Erreur lors de la création des privilèges du rôle"

#: src/backend/models/splitter.py:69
msgid "GET_MAX_SPLIT_INDEX_ERROR"
msgstr "Erreur lors de l'obtention de l'index du Splitter"

#: src/backend/models/splitter.py:110
msgid "UPDATE_SETTINGS_ERROR"
msgstr "Erreur lors de la mise à jour des paramètres du Splitter"

#: src/backend/models/splitter.py:132
msgid "INSERT_PAGE_ERROR"
msgstr "Erreur lors de l'insertion des pages du Splitter"

#: src/backend/models/splitter.py:193
msgid "GET_BATCH_ERROR"
msgstr "Erreur lors de la récupération des lots du Splitter"

#: src/backend/models/splitter.py:213
msgid "GET_DOCUMENTS_ERROR"
msgstr "Erreur lors de la récupération des documents du Splitter"

#: src/backend/models/splitter.py:233
msgid "GET_PAGES_ERROR"
msgstr "Erreur lors de l'obtention des pages du Splitter"

#: src/backend/models/splitter.py:252
msgid "GET_MAX_SOURCE_PAGE_VALUE_ERROR"
msgstr "Erreur lors de l'obtention de la valeur des pages source du Splitter"

#: src/backend/models/splitter.py:272
msgid "GET_DOCUMENT_ERROR"
msgstr "Erreur lors de la récupération du document"

#: src/backend/models/splitter.py:291
msgid "GET_DOCUMENT_MAX_SPLIT_INDEX_ERROR"
msgstr "Erreur lors de l'obtention de l'index maximum du Splitter"

#: src/backend/models/status.py:37
msgid "NO_STATUS"
msgstr "Aucun status existant"

#: src/backend/models/user.py:44
msgid "USER"
msgstr "L'utilisateur"

#: src/backend/models/user.py:44
msgid "ALREADY_REGISTERED"
msgstr "est déjà enregistré"

#: src/backend/models/verifier.py:92 src/backend/models/verifier.py:110
msgid "INVOICE_UPDATE_ERROR"
msgstr "Erreur lors de la mise à jour de la facture"

#: src/backend/rest/auth.py:46 src/backend/rest/auth.py:94
msgid "PGSQL_ERROR"
msgstr "Erreur lors de la connexion à la base de donnée"

#: src/backend/rest/auth.py:79 src/backend/rest/auth.py:257
#: src/backend/rest/auth.py:271 src/backend/rest/auth.py:280
#: src/backend/rest/auth.py:285 src/backend/rest/auth.py:474
msgid "LDAP_CONNECTION_ERROR"
msgstr "Impossible de se connecter au serveur LDAP"

#: src/backend/rest/auth.py:80
msgid "LOGIN_LDAP_ERROR"
msgstr "Information(s) de connexion incorrecte(s)"

#: src/backend/rest/auth.py:205
msgid "AUTH_METHOD_ERROR"
msgstr "Aucune methode d'authentification n'est activée"

#: src/backend/rest/auth.py:210
msgid "SEVERAL_AUTH_METHODS_ENABLED"
msgstr "Plusieurs méthodes d'authentification sont activées"

#: src/backend/rest/auth.py:223
msgid "LDAP_ERROR"
msgstr "Erreur LDAP"

#: src/backend/rest/auth.py:255 src/backend/rest/auth.py:269
#: src/backend/rest/auth.py:278
msgid "BAD_CONNECTION_LDAP_INFOS"
msgstr "Information(s) incorrecte(s)"

#: src/backend/rest/auth.py:289
msgid "NOT_COMPLETE_CONNECTION_INFOS"
msgstr "Il manque une ou plusieurs informations pour établir la connexion"

#: src/backend/rest/auth.py:291 src/backend/rest/auth.py:479
#: src/backend/rest/auth.py:485
msgid "INFOS_LDAP_NOT_COMPLETE"
msgstr "Informations non complètes"

#: src/backend/rest/auth.py:461 src/backend/rest/auth.py:467
#: src/backend/rest/auth.py:473 src/backend/rest/auth.py:478
#: src/backend/rest/auth.py:484
msgid "LDAP_SYNCHRO_ERROR"
msgstr "Erreur lors de la synchronisation LDAP"

#: src/backend/rest/auth.py:462 src/backend/rest/auth.py:468
msgid "LDAP_SYNCHRO_INFOS_ERROR"
msgstr "Information(s) de synchronisation incorrecte(s)"

#: src/backend/rest/auth.py:497 src/backend/rest/auth.py:524
#: src/backend/rest/auth.py:538
msgid "REQUEST_MODIFS_ERROR"
msgstr "Erreur base de données impossible d'exécuter la requête"

#: src/backend/rest/auth.py:510
msgid "RETRIEVE_LOGIN_METHODS_ERROR"
msgstr "Erreur lors du chargement des méthodes d'authentification"

#: src/backend/rest/splitter.py:39 src/backend/rest/verifier.py:37
msgid "UNKNOW_ERROR"
msgstr "Erreur inconnue"

#~ msgid "ADD_DOC_TYPE_ERROR"
#~ msgstr "Error while adding document type"

#~ msgid "CHANGE_LOCALE_ERROR"
#~ msgstr "Erreur lors du changement de langue"

#~ msgid "INPUT_FOLDER_DOESNT_EXISTS_OR_NOT_WRITEABLE"
#~ msgstr "Le dossier spécifié n'existe pas ou n'est pas accessible"

#~ msgid "GET_DEMAND_NUMBER_ERROR"
#~ msgstr "Erreur lors de l'obtention du numéro de demande du Splitter"

#~ msgid "INSERT_REFERENTIAL_ERROR"
#~ msgstr "Erreur lors de l'insertion du référentiel de Splitter"

